//The exception is already declared in "main" method